Workbook

Sheet 개요
A1: STT 검증셋 50건 — 선별 근거 · 낭독 규칙
A2: 문진 대화 727건 중 KTAS 레벨별 10건씩 선별해 직접 낭독·녹음한 STT 전사 정확도 검증셋의 요약입니다.
A4: 시트 구성
A5: 선별근거 | B5: 50건 각각의 KTAS 레벨·분류·길이·녹음 길이·의학 도메인 특징(활력징후, 의학용어, 영문 약어). index와 음성 파일명(index.m4a)이 1:1로 대응.
A6: 낭독규칙표 | B6: 숫자·단위·영문 약어·기호를 한글로 읽는 통일 규칙 32개. 녹음 기준이자 STT 출력 정규화 기준.
A8: KTAS 레벨별 요약 (선별근거 시트에서 자동 계산)
A9: KTAS 레벨 | B9: 건수 | C9: 평균 턴 수 | D9: 턴 수 범위 | E9: 총 발화 수 | F9: 15세 미만 | G9: 모름류 발화 포함 대화 | H9: 녹음 길이 합계(분) | I9: 평균 발화 속도 (글자/초)
A10: 1 | B10: =COUNTIF('선별근거'!$C$2:$C$51,A10) -> 10 | C10: =ROUND(AVERAGEIF('선별근거'!$C$2:$C$51,A10,'선별근거'!$H$2:$H$51),1) -> 8.8 | D10: =MINIFS('선별근거'!$H$2:$H$51,'선별근거'!$C$2:$C$51,A10)&"–"&MAXIFS('선별근거'!$H$2:$H$51,'선별근거'!$C$2:$C$51,A10) -> 8–10 | E10: =SUMIF('선별근거'!$C$2:$C$51,A10,'선별근거'!$I$2:$I$51) -> 159 | F10: =COUNTIFS('선별근거'!$C$2:$C$51,A10,'선별근거'!$F$2:$F$51,"15세 미만") -> 1 | G10: =COUNTIFS(선별근거!$C$2:$C$51,A10,선별근거!#REF!,">0") -> #ERROR! | H10: =ROUND(SUMIF('선별근거'!$C$2:$C$51,A10,'선별근거'!$K$2:$K$51)/60,1) -> 8.6 | I10: =ROUND(SUMIF('선별근거'!$C$2:$C$51,A10,'선별근거'!$J$2:$J$51)/SUMIF('선별근거'!$C$2:$C$51,A10,'선별근거'!$K$2:$K$51),2) -> 5.69
A11: 2 | B11: =COUNTIF('선별근거'!$C$2:$C$51,A11) -> 10 | C11: =ROUND(AVERAGEIF('선별근거'!$C$2:$C$51,A11,'선별근거'!$H$2:$H$51),1) -> 11 | D11: =MINIFS('선별근거'!$H$2:$H$51,'선별근거'!$C$2:$C$51,A11)&"–"&MAXIFS('선별근거'!$H$2:$H$51,'선별근거'!$C$2:$C$51,A11) -> 8–14 | E11: =SUMIF('선별근거'!$C$2:$C$51,A11,'선별근거'!$I$2:$I$51) -> 215 | F11: =COUNTIFS('선별근거'!$C$2:$C$51,A11,'선별근거'!$F$2:$F$51,"15세 미만") -> 2 | G11: =COUNTIFS(선별근거!$C$2:$C$51,A11,선별근거!#REF!,">0") -> #ERROR! | H11: =ROUND(SUMIF('선별근거'!$C$2:$C$51,A11,'선별근거'!$K$2:$K$51)/60,1) -> 9.8 | I11: =ROUND(SUMIF('선별근거'!$C$2:$C$51,A11,'선별근거'!$J$2:$J$51)/SUMIF('선별근거'!$C$2:$C$51,A11,'선별근거'!$K$2:$K$51),2) -> 5.22
A12: 3 | B12: =COUNTIF('선별근거'!$C$2:$C$51,A12) -> 10 | C12: =ROUND(AVERAGEIF('선별근거'!$C$2:$C$51,A12,'선별근거'!$H$2:$H$51),1) -> 11.6 | D12: =MINIFS('선별근거'!$H$2:$H$51,'선별근거'!$C$2:$C$51,A12)&"–"&MAXIFS('선별근거'!$H$2:$H$51,'선별근거'!$C$2:$C$51,A12) -> 9–15 | E12: =SUMIF('선별근거'!$C$2:$C$51,A12,'선별근거'!$I$2:$I$51) -> 228 | F12: =COUNTIFS('선별근거'!$C$2:$C$51,A12,'선별근거'!$F$2:$F$51,"15세 미만") -> 1 | G12: =COUNTIFS(선별근거!$C$2:$C$51,A12,선별근거!#REF!,">0") -> #ERROR! | H12: =ROUND(SUMIF('선별근거'!$C$2:$C$51,A12,'선별근거'!$K$2:$K$51)/60,1) -> 9.9 | I12: =ROUND(SUMIF('선별근거'!$C$2:$C$51,A12,'선별근거'!$J$2:$J$51)/SUMIF('선별근거'!$C$2:$C$51,A12,'선별근거'!$K$2:$K$51),2) -> 5.36
A13: 4 | B13: =COUNTIF('선별근거'!$C$2:$C$51,A13) -> 10 | C13: =ROUND(AVERAGEIF('선별근거'!$C$2:$C$51,A13,'선별근거'!$H$2:$H$51),1) -> 10 | D13: =MINIFS('선별근거'!$H$2:$H$51,'선별근거'!$C$2:$C$51,A13)&"–"&MAXIFS('선별근거'!$H$2:$H$51,'선별근거'!$C$2:$C$51,A13) -> 8–12 | E13: =SUMIF('선별근거'!$C$2:$C$51,A13,'선별근거'!$I$2:$I$51) -> 196 | F13: =COUNTIFS('선별근거'!$C$2:$C$51,A13,'선별근거'!$F$2:$F$51,"15세 미만") -> 3 | G13: =COUNTIFS(선별근거!$C$2:$C$51,A13,선별근거!#REF!,">0") -> #ERROR! | H13: =ROUND(SUMIF('선별근거'!$C$2:$C$51,A13,'선별근거'!$K$2:$K$51)/60,1) -> 8.6 | I13: =ROUND(SUMIF('선별근거'!$C$2:$C$51,A13,'선별근거'!$J$2:$J$51)/SUMIF('선별근거'!$C$2:$C$51,A13,'선별근거'!$K$2:$K$51),2) -> 5.27
A14: 5 | B14: =COUNTIF('선별근거'!$C$2:$C$51,A14) -> 10 | C14: =ROUND(AVERAGEIF('선별근거'!$C$2:$C$51,A14,'선별근거'!$H$2:$H$51),1) -> 8.2 | D14: =MINIFS('선별근거'!$H$2:$H$51,'선별근거'!$C$2:$C$51,A14)&"–"&MAXIFS('선별근거'!$H$2:$H$51,'선별근거'!$C$2:$C$51,A14) -> 8–9 | E14: =SUMIF('선별근거'!$C$2:$C$51,A14,'선별근거'!$I$2:$I$51) -> 141 | F14: =COUNTIFS('선별근거'!$C$2:$C$51,A14,'선별근거'!$F$2:$F$51,"15세 미만") -> 0 | G14: =COUNTIFS(선별근거!$C$2:$C$51,A14,선별근거!#REF!,">0") -> #ERROR! | H14: =ROUND(SUMIF('선별근거'!$C$2:$C$51,A14,'선별근거'!$K$2:$K$51)/60,1) -> 6.2 | I14: =ROUND(SUMIF('선별근거'!$C$2:$C$51,A14,'선별근거'!$J$2:$J$51)/SUMIF('선별근거'!$C$2:$C$51,A14,'선별근거'!$K$2:$K$51),2) -> 5.61
A15: 합계 | B15: =SUM(B10:B14) -> 50 | C15: =ROUND(AVERAGE('선별근거'!$H$2:$H$51),1) -> 9.9 | D15: =MIN('선별근거'!$H$2:$H$51)&"–"&MAX('선별근거'!$H$2:$H$51) -> 8–15 | E15: =SUM(E10:E14) -> 939 | F15: =SUM(F10:F14) -> 7 | G15: =SUM(G10:G14) -> #ERROR! | H15: =ROUND(SUM('선별근거'!$K$2:$K$51)/60,1) -> 43.1 | I15: =ROUND(SUM('선별근거'!$J$2:$J$51)/SUM('선별근거'!$K$2:$K$51),2) -> 5.41

Sheet 선별근거
A1: index | B1: 음성 파일 | C1: KTAS 레벨 | D1: 대분류 | E1: 중분류 | F1: 나이 | G1: 응답 화자 | H1: 턴 수 | I1: 발화 수 | J1: 낭독본 글자 수 (공백 제외) | K1: 녹음 길이(초) | L1: 발화 속도 (글자/초) | M1: 활력징후 항목 | N1: 통증점수(NRS 등) 포함 | O1: 수치 토큰 수 | P1: 영문·약어 표기 | Q1: 의학용어(사전 매칭)
A2: 0 | B2: 0.m4a | C2: 2 | D2: 근골격계 | E2: 목, 등, 허리 통증 | F2: 15세 이상 | G2: 환자측 | H2: 13 | I2: 26 | J2: 353 | K2: 70 | L2: =ROUND(J2/K2,2) -> 5.04 | M2: 혈압, 맥박, 호흡수, 체온, 산소포화도 | N2: Y | O2: 9 | P2: MOTOR, NRS, POWER, mmHg | Q2: NRS, mmHg, 감각, 과거력, 근력, 디스크, 맥박, 산소포화도, 소변, 수술, 저림, 체온, 혈압, 호흡, 활력징후
A3: 107 | B3: 107.m4a | C3: 3 | D3: 임신/여성생식계 | E3: 월경 문제 | F3: 15세 이상 | G3: 환자측 | H3: 11 | I3: 22 | J3: 279 | K3: 56.6 | L3: =ROUND(J3/K3,2) -> 4.93 | M3: 혈압, 맥박, 호흡수, 체온, 산소포화도 | N3: Y | O3: 9 | P3: Alert, NRS, SPO2, mmHg | Q3: NRS, SPO2, mmHg, 과거력, 맥박, 복용, 복통, 생리, 의식, 진통제, 체온, 혈압, 호흡, 활력징후
A4: 112 | B4: 112.m4a | C4: 3 | D4: 근골격계 | E4: 외상성 목, 등, 허리 손상 | F4: 15세 이상 | G4: 환자측 | H4: 15 | I4: 30 | J4: 353 | K4: 72 | L4: =ROUND(J4/K4,2) -> 4.9 | M4: 혈압, 맥박, 호흡수, 체온, 산소포화도 | N4: Y | O4: 13 | P4: SPO2, mmHg | Q4: SPO2, mmHg, 구토, 맥박, 외상, 저림, 체온, 혈압, 호흡, 활력징후
A5: 126 | B5: 126.m4a | C5: 4 | D5: 입,목/얼굴 | E5: 인후통 | F5: 15세 미만 | G5: 환자측 | H5: 10 | I5: 20 | J5: 218 | K5: 45.8 | L5: =ROUND(J5/K5,2) -> 4.76 | M5: 혈압, 맥박, 호흡수, 체온, 산소포화도 | N5: Y | O5: 9 | P5: FPRS, SPO2, mmHg | Q5: SPO2, mmHg, 맥박, 외상, 인후통, 체온, 혈압, 호흡, 활력징후
A6: 128 | B6: 128.m4a | C6: 4 | D6: 피부 | E6: 감염 가능성 확인 | F6: 15세 이상 | G6: 환자측 | H6: 12 | I6: 24 | J6: 251 | K6: 52.9 | L6: =ROUND(J6/K6,2) -> 4.74 | M6: 혈압, 맥박, 호흡수, 체온, 산소포화도, 혈당 | N6: Y | O6: 11 | P6: BST, NRS, SPO2, mg/dL, mmHg | Q6: BST, NRS, SPO2, mmHg, 과거력, 당뇨, 맥박, 발적, 부종, 체온, 혈압, 호흡, 화상, 활력징후
A7: 140 | B7: 140.m4a | C7: 4 | D7: 근골격계 | E7: 하지 통증 | F7: 15세 이상 | G7: 환자측 | H7: 12 | I7: 24 | J7: 328 | K7: 64.4 | L7: =ROUND(J7/K7,2) -> 5.09 | M7: 혈압, 맥박, 호흡수, 체온, 산소포화도 | N7: Y | O7: 10 | P7: NRS, SPO2, mmHg | Q7: NRS, SPO2, mmHg, 고혈압, 당뇨, 맥박, 발적, 외상, 체온, 혈압, 호흡, 활력징후
A8: 146 | B8: 146.m4a | C8: 2 | D8: 신경계 | E8: 사지약화/뇌졸중 증상 | F8: 15세 이상 | G8: 환자측 | H8: 14 | I8: 28 | J8: 380 | K8: 74.4 | L8: =ROUND(J8/K8,2) -> 5.11 | M8: 혈압, 맥박, 호흡수, 체온, 산소포화도, GCS | N8: Y | O8: 14 | P8: GCS, SPO2, grade, mmHg, motor | Q8: GCS, SPO2, mmHg, 감각, 고지혈증, 고혈압, 과거력, 근력, 맥박, 외상, 지혈, 체온, 혈압, 호흡, 활력징후
A9: 148 | B9: 148.m4a | C9: 2 | D9: 신경계 | E9: 발작 | F9: 15세 이상 | G9: 환자측 | H9: 9 | I9: 18 | J9: 269 | K9: 54.4 | L9: =ROUND(J9/K9,2) -> 4.94 | M9: 혈압, 맥박, 호흡수, 체온, 산소포화도, GCS | N9: Y | O9: 9 | P9: GCS, SPO2, mmHg, stupor | Q9: GCS, SPO2, mmHg, 경련, 과거력, 기면, 맥박, 발작, 복용, 의식, 체온, 혈압, 호흡, 활력징후
A10: 152 | B10: 152.m4a | C10: 2 | D10: 심혈관계 | E10: 흉통(심장성) | F10: 15세 이상 | G10: 환자측 | H10: 13 | I10: 26 | J10: 338 | K10: 67 | L10: =ROUND(J10/K10,2) -> 5.04 | M10: 혈압, 맥박, 호흡수, 체온, 산소포화도 | N10: Y | O10: 10 | P10: NRS, SPO2, mmHg | Q10: NRS, SPO2, mmHg, 가슴통증, 고혈압, 과거력, 맥박, 체온, 혈압, 호흡, 호흡곤란, 활력징후
A11: 158 | B11: 158.m4a | C11: 2 | D11: 호흡기계 | E11: 알레르기반응 | F11: 15세 미만 | G11: 환자측 | H11: 10 | I11: 20 | J11: 255 | K11: 50 | L11: =ROUND(J11/K11,2) -> 5.1 | M11: 혈압, 맥박, 호흡수, 체온, 산소포화도 | N11: N | O11: 8 | P11: SPO2, mmHg | Q11: SPO2, mmHg, 과거력, 맥박, 발진, 쌕쌕, 알러지, 체온, 혈압, 호흡, 활력징후
A12: 160 | B12: 160.m4a | C12: 2 | D12: 임신/여성생식계 | E12: 20주 이상의 임신 | F12: 15세 이상 | G12: 환자측 | H12: 10 | I12: 20 | J12: 288 | K12: 54.6 | L12: =ROUND(J12/K12,2) -> 5.27 | M12: 혈압, 맥박, 호흡수, 체온, 산소포화도 | N12: N | O12: 9 | P12: SPO2, mmHg | Q12: SPO2, mmHg, 과거력, 맥박, 복용, 복통, 양수, 외상, 임신, 질출혈, 체온, 출혈, 태동, 혈압, 호흡, 활력징후
A13: 166 | B13: 166.m4a | C13: 2 | D13: 소화기계 | E13: 복통 | F13: 15세 이상 | G13: 환자측 | H13: 10 | I13: 20 | J13: 274 | K13: 51.2 | L13: =ROUND(J13/K13,2) -> 5.35 | M13: 혈압, 맥박, 호흡수, 체온, 산소포화도 | N13: Y | O13: 11 | P13: NRS, SPO2, mmHg | Q13: NRS, SPO2, mmHg, 구토, 맥박, 설사, 체온, 혈압, 호흡, 활력징후
... A28: 520 | B28: 520.m4a | C28: 2 | D28: 심혈관계 | E28: 고혈압 | F28: 15세 이상 | G28: 환자 | H28: 10 | I28: 18 | J28: 305 | K28: 55 | L28: =ROUND(J28/K28,2) -> 5.55 | M28: 혈압, 맥박, 호흡수, 체온, 산소포화도 | N28: N | O28: 8 | P28: ESRD | Q28: 가슴통증, 고혈압, 두통, 맥박, 산소포화도, 체온, 투석, 혈압, 혈압약, 호흡
A29: 529 | B29: 529.m4a | C29: 3 | D29: 환경손상 | E29: 유해물질흡입 | F29: 15세 이상 | G29: 환자 | H29: 10 | I29: 19 | J29: 290 | K29: 53.6 | L29: =ROUND(J29/K29,2) -> 5.41 | M29: 혈압, 맥박, 호흡수, 체온, 산소포화도 | N29: N | O29: 6 | Q29: 기침, 맥박, 산소포화도, 체온, 혈압, 호흡
A30: 530 | B30: 530.m4a | C30: 3 | D30: 소화기계 | E30: 토혈 | F30: 15세 미만 | G30: 보호자 | H30: 9 | I30: 15 | J30: 317 | K30: 53.5 | L30: =ROUND(J30/K30,2) -> 5.93 | M30: 혈압, 맥박, 호흡수, 체온 | N30: N | O30: 6 | P30: mmHg | Q30: mmHg, 구토, 맥박, 복통, 의식, 체온, 혈압, 호흡, 활력징후
A31: 533 | B31: 533.m4a | C31: 4 | D31: 심혈관계 | E31: 흉통(비심장성) | F31: 15세 미만 | G31: 보호자/환자 | H31: 8 | I31: 15 | J31: 264 | K31: 46.9 | L31: =ROUND(J31/K31,2) -> 5.63 | M31: 혈압, 맥박, 호흡수, 체온, 산소포화도 | N31: Y | O31: 9 | P31: SPO2, mmHg | Q31: SPO2, mmHg, 맥박, 체온, 혈압, 호흡, 활력징후
A32: 568 | B32: 568.m4a | C32: 1 | D32: 호흡기계 | E32: 숨참 | F32: 15세 이상 | G32: 환자측 | H32: 8 | I32: 15 | J32: 352 | K32: 63.9 | L32: =ROUND(J32/K32,2) -> 5.51 | M32: 혈압, 맥박, 호흡수, 체온, 산소포화도 | N32: N | O32: 10 | P32: Mental, V/S, mmHg | Q32: V/S, mmHg, 과거력, 구음장애, 마비, 맥박, 명료, 보행, 산소포화도, 의식, 체온, 편마비, 혈압, 호흡, 호흡곤란, 활력징후
A33: 585 | B33: 585.m4a | C33: 1 | D33: 심혈관계 | E33: 심계항진/불규칙한 심장박동 | F33: 15세 이상 | G33: 환자측 | H33: 8 | I33: 16 | J33: 286 | K33: 52.1 | L33: =ROUND(J33/K33,2) -> 5.49 | M33: 혈압, 맥박, 호흡수, 체온 | N33: N | O33: 8 | P33: V/S, mmHg | Q33: V/S, mmHg, 과거력, 맥박, 체온, 혈압, 호흡, 활력징후, 흉통
A34: 625 | B34: 625.m4a | C34: 5 | D34: 근골격계 | E34: 하지 손상 | F34: 15세 이상 | G34: 환자측 | H34: 9 | I34: 17 | J34: 274 | K34: 48.6 | L34: =ROUND(J34/K34,2) -> 5.64 | M34: 혈압, 맥박, 호흡수, 체온, 산소포화도 | N34: Y | O34: 8 | P34: NRS, V/S, mmHg | Q34: NRS, V/S, mmHg, 감각, 골절, 맥박, 산소포화도, 체온, 혈압, 호흡, 활력징후
A35: 629 | B35: 629.m4a | C35: 1 | D35: 비뇨기계/남성생식계 | E35: 혈뇨 | F35: 15세 이상 | G35: 환자측 | H35: 8 | I35: 15 | J35: 243 | K35: 43.9 | L35: =ROUND(J35/K35,2) -> 5.54 | M35: 혈압, 맥박, 호흡수, 체온, 산소포화도 | N35: N | O35: 7 | P35: V/S, mmHg | Q35: V/S, mmHg, 과거력, 맥박, 복용, 산소포화도, 소변, 약물, 어지럼, 옆구리, 와파린, 체온, 혈뇨, 혈압, 호흡, 활력징후
A36: 679 | B36: 679.m4a | C36: 1 | D36: 몸통외상 | E36: 단독 복부외상-둔상 | F36: 15세 이상 | G36: 119대원/환자 | H36: 8 | I36: 13 | J36: 284 | K36: 49.1 | L36: =ROUND(J36/K36,2) -> 5.78 | M36: 혈압, 맥박, 호흡수, 체온, 산소포화도 | N36: N | O36: 6 | P36: mmHg | Q36: mmHg, 맥박, 복부, 산소포화도, 외상, 체온, 출혈, 혈압, 호흡, 활력징후
A37: 681 | B37: 681.m4a | C37: 1 | D37: 신경계 | E37: 의식수준의 변화 | F37: 15세 이상 | G37: 보호자 | H37: 10 | I37: 19 | J37: 329 | K37: 56.6 | L37: =ROUND(J37/K37,2) -> 5.81 | M37: 혈압, 맥박, 호흡수, 체온 | N37: N | O37: 7 | Q37: 경련, 뇌졸중, 맥박, 의식, 체온, 혈압, 호흡
A38: 683 | B38: 683.m4a | C38: 1 | D38: 심혈관계 | E38: 실신/전실신 | F38: 15세 이상 | G38: 119대원/환자 | H38: 8 | I38: 13 | J38: 311 | K38: 54.2 | L38: =ROUND(J38/K38,2) -> 5.74 | M38: 혈압, 맥박, 호흡수, 체온, 산소포화도 | N38: N | O38: 9 | P38: cc | Q38: 가슴통증, 맥박, 산소포화도, 수액, 실신, 어지럼, 체온, 혈압, 호흡
A39: 684 | B39: 684.m4a | C39: 1 | D39: 환경손상 | E39: 온열손상 | F39: 15세 이상 | G39: 보호자 | H39: 9 | I39: 17 | J39: 272 | K39: 46.8 | L39: =ROUND(J39/K39,2) -> 5.81 | M39: 혈압, 맥박, 호흡수, 체온, 산소포화도 | N39: N | O39: 6 | Q39: 기저질환, 맥박, 산소포화도, 의식, 체온, 혈압, 호흡
A40: 686 | B40: 686.m4a | C40: 1 | D40: 물질오용 | E40: 물질금단 | F40: 15세 이상 | G40: 보호자 | H40: 10 | I40: 18 | J40: 279 | K40: 49.3 | L40: =ROUND(J40/K40,2) -> 5.66 | M40: 혈압, 맥박, 산소포화도 | N40: N | O40: 5 | Q40: 간경화, 경련, 맥박, 산소포화도, 혈압
A41: 687 | B41: 687.m4a | C41: 1 | D41: 정신건강 | E41: 폭력/살인행위 | F41: 15세 이상 | G41: 가족/환자 | H41: 10 | I41: 18 | J41: 302 | K41: 50.9 | L41: =ROUND(J41/K41,2) -> 5.93 | M41: 혈압, 맥박, 호흡수 | N41: N | O41: 4 | Q41: 맥박, 산소포화도, 혈압, 호흡
A42: 693 | B42: 693.m4a | C42: 1 | D42: 몸통외상 | E42: 몸통을 포함한 다발성 외상-둔상 | F42: 15세 미만 | G42: 보호자/환자 | H42: 9 | I42: 15 | J42: 260 | K42: 46.2 | L42: =ROUND(J42/K42,2) -> 5.63 | M42: 맥박, 호흡수, 산소포화도 | N42: Y | O42: 5 | Q42: 맥박, 산소포화도, 호흡, 활력징후
A43: 698 | B43: 698.m4a | C43: 5 | D43: 코 | E43: 코막힘 | F43: 15세 이상 | G43: 환자 | H43: 8 | I43: 14 | J43: 232 | K43: 41.4 | L43: =ROUND(J43/K43,2) -> 5.6 | M43: 혈압, 맥박, 호흡수, 체온, 산소포화도 | N43: N | O43: 6 | Q43: 맥박, 산소포화도, 체온, 혈압, 호흡, 활력징후
A44: 699 | B44: 699.m4a | C44: 5 | D44: 귀 | E44: 귀의 이물질 | F44: 15세 이상 | G44: 환자 | H44: 8 | I44: 13 | J44: 179 | K44: 31.3 | L44: =ROUND(J44/K44,2) -> 5.72 | M44: 혈압, 맥박, 호흡수, 체온, 산소포화도 | N44: N | O44: 6 | Q44: 맥박, 산소포화도, 청력, 체온, 혈압, 호흡, 활력징후
A45: 700 | B45: 700.m4a | C45: 5 | D45: 귀 | E45: 귀의 손상 | F45: 15세 이상 | G45: 환자 | H45: 8 | I45: 13 | J45: 180 | K45: 33.6 | L45: =ROUND(J45/K45,2) -> 5.36 | M45: 혈압, 맥박, 호흡수, 체온, 산소포화도 | N45: N | O45: 6 | Q45: 맥박, 산소포화도, 체온, 출혈, 혈압, 호흡, 활력징후
A46: 703 | B46: 703.m4a | C46: 5 | D46: 소화기계 | E46: 직장내 이물질 | F46: 15세 이상 | G46: 환자 | H46: 8 | I46: 13 | J46: 177 | K46: 31.3 | L46: =ROUND(J46/K46,2) -> 5.65 | M46: 혈압, 맥박, 호흡수, 체온, 산소포화도 | N46: Y | O46: 7 | Q46: 맥박, 복통, 산소포화도, 체온, 출혈, 혈압, 호흡, 활력징후
A47: 704 | B47: 704.m4a | C47: 5 | D47: 소화기계 | E47: 샅고랑부위(Groin)통증/종괴 | F47: 15세 이상 | G47: 환자 | H47: 8 | I47: 13 | J47: 186 | K47: 34.2 | L47: =ROUND(J47/K47,2) -> 5.44 | M47: 혈압, 맥박, 호흡수, 체온, 산소포화도 | N47: Y | O47: 7 | Q47: 맥박, 산소포화도, 체온, 혈압, 호흡, 활력징후
A48: 707 | B48: 707.m4a | C48: 5 | D48: 소화기계 | E48: 복부종괴/팽만 | F48: 15세 이상 | G48: 환자 | H48: 9 | I48: 16 | J48: 251 | K48: 44.4 | L48: =ROUND(J48/K48,2) -> 5.65 | M48: 혈압, 맥박, 호흡수, 체온 | N48: Y | O48: 6 | Q48: 구토, 맥박, 복부, 복통, 체온, 혈압, 호흡
A49: 708 | B49: 708.m4a | C49: 5 | D49: 임신/여성생식계 | E49: 질내 이물질 | F49: 15세 이상 | G49: 환자 | H49: 8 | I49: 14 | J49: 197 | K49: 34.7 | L49: =ROUND(J49/K49,2) -> 5.68 | M49: 혈압, 맥박, 호흡수, 체온 | N49: N | O49: 5 | Q49: 맥박, 복통, 체온, 출혈, 혈압, 호흡
A50: 709 | B50: 709.m4a | C50: 5 | D50: 임신/여성생식계 | E50: 음순부종 | F50: 15세 이상 | G50: 환자 | H50: 8 | I50: 14 | J50: 192 | K50: 34 | L50: =ROUND(J50/K50,2) -> 5.65 | M50: 혈압, 맥박, 호흡수, 체온 | N50: N | O50: 5 | Q50: 가려움, 맥박, 부종, 체온, 출혈, 혈압, 호흡
A51: 717 | B51: 717.m4a | C51: 5 | D51: 피부 | E51: 유방의 발적/압통 | F51: 15세 이상 | G51: 환자 | H51: 8 | I51: 14 | J51: 234 | K51: 41.1 | L51: =ROUND(J51/K51,2) -> 5.69 | M51: 혈압, 맥박, 호흡수, 체온, 산소포화도 | N51: N | O51: 6 | Q51: 맥박, 산소포화도, 체온, 혈압, 호흡, 활력징후
A53: ※ 녹음 길이: 소리_녹음.zip의 음성 파일(index.m4a)을 ffprobe로 실측한 값.
A54: ※ 낭독본 글자 수: STT_검증셋_50_낭독용.csv의 한글 낭독본에서 화자 태그·공백을 뺀 글자 수 (CER 계산 시 정답 길이).
A55: ※ 의학용어·영문 약어·활력징후 항목: 원문 대화에서 사전/정규식으로 자동 추출한 목록 (의학용어 재현율·수치 정확도 산출용 정답 후보).
...

Sheet 낭독규칙표
A1: 번호 | B1: 구분 | C1: 원문 표기 | D1: 낭독 방법(통일) | E1: 예시 (원문 → 낭독본) | F1: 50건 내 등장 횟수 | G1: 비고
A2: 1 | B2: 공통 | C2: [T01] 의료진: 등 화자 태그 | D2: 읽지 않음 | G2: 녹음 시 역할 구분용 표시. CER 계산 시에도 제거
A3: 2 | B3: 공통 | C3: 쉼표·마침표·말줄임표(…)·물음표 | D3: 읽지 않고 쉼으로 처리 | G3: CER 계산 시 문장부호는 제거
A4: 3 | B4: 숫자 | C4: 기본 숫자 읽기 | D4: 한자어 수사(일, 이, 삼 …) | E4: 맥박 122, 호흡수 24 → 맥박 백이십이, 호흡수 이십사 | F4: 499 | G4: 환자 번호(번), 나이(세), 점수(점), 횟수(회), 일·주·개월·대, 단위 없는 활력징후 수치 모두 해당
A5: 4 | B5: 숫자 | C5: 0 | D5: 영 | E5: 통증 0~10점 기준 → 통증 영에서 십 점 기준 | F5: 6 | G5: '공' 사용하지 않음
A6: 5 | B6: 숫자 | C6: 소수점 (.) | D6: 점, 소수부는 한 자리씩 | E6: 체온 37.0℃ → 체온 삼십칠 점 영 도 | F6: 46 | G6: '쩜' 대신 '점'으로 표기
A7: 6 | B7: 숫자 | C7: N살 / N시간 / N시(시각) | D7: 고유어 수사(한, 두, 세 … 스물네, 일흔다섯) | E7: 28살 → 스물여덟 살 / 24시간 이내 → 스물네 시간 이내 / 밤 9시부터 → 밤 아홉 시부터 | F7: 10 | G7: '세'는 한자어(오십 세), '살'은 고유어(스물여덟 살)로 원문 단위를 따름
A8: 7 | B8: 숫자 | C8: 119 | D8: 일일구 | E8: 119 부르고 왔어요 → 일일구 부르고 왔어요 | F8: 5 | G8: 신고 번호는 자릿수대로
A9: 8 | B9: 숫자 | C9: 범위 (~) | D9: 연속한 한 자리 수는 붙여 읽기, 그 외는 A에서 B | E9: 3~4일 전부터 → 삼사 일 전부터 / 1~2분이면 → 일이 분이면 / 0~10점 → 영에서 십 점 | F9: 3
A10: 9 | B10: 활력징후 | C10: 혈압 A/B | D10: A에 B | E10: 혈압 130/80 → 혈압 백삼십에 팔십 | F10: 50 | G10: '슬래시', '오버'로 읽지 않음
A11: 10 | B11: 단위 | C11: mmHg | D11: 엠엠에이치지 | E11: 혈압 125/80 mmHg → 혈압 백이십오에 팔십 엠엠에이치지 | F11: 33 | G11: 현장 관용 발음 채택. 표준 명칭 '수은주밀리미터'로 바꿀 경우 이 행만 교체
A12: 11 | B12: 단위 | C12: 회/분 | D12: 분당 N 회 | E12: 맥박 76회/분 → 맥박 분당 칠십육 회 | F12: 65 | G12: '회 퍼 분'으로 읽지 않음
A13: 12 | B13: 단위 | C13: ℃ / °C / 도 | D13: 도 (섭씨 생략) | E13: 체온 36.6℃ → 체온 삼십육 점 육 도 / 체온 36.7도 → 체온 삼십육 점 칠 도 | F13: 47
A14: 13 | B14: 단위 | C14: % | D14: 퍼센트 | E14: 산소포화도 98% → 산소포화도 구십팔 퍼센트 | F14: 42 | G14: '프로'로 읽지 않음
A15: 14 | B15: 단위 | C15: mg/dL | D15: 밀리그램 퍼 데시리터 | E15: BST 220mg/dL이에요 → 비에스티 이백이십 밀리그램 퍼 데시리터예요 | F15: 1 | G15: 조사도 발음에 맞춰 교정(이에요→예요)
A16: 15 | B16: 단위 | C16: cc | D16: 씨씨 | E16: 수액 500cc → 수액 오백 씨씨 | F16: 1
A17: 16 | B17: 단위 | C17: kg | D17: 킬로그램 | E17: 약 5kg 정도 → 약 오 킬로그램 정도 | F17: 1 | G17: '킬로'로 줄이지 않음
A18: 17 | B18: 단위 | C18: 근력 등급 N/5 | D18: 오 분의 N | E18: 근력은 4/5입니다 → 근력은 오 분의 사입니다 | F18: 3
A19: 18 | B19: 약어 | C19: SpO2 / SPO2 | D19: 에스피오투 | E19: SPO2 98% → 에스피오투 구십팔 퍼센트 | F19: 24 | G19: 알파벳은 관용 발음(C=씨, R=알)으로 통일. '산소포화도'로 바꿔 읽지 않음
A20: 19 | B20: 약어 | C20: V/S | D20: 브이에스 | E20: V/S 알려주세요 → 브이에스 알려주세요 | F20: 5
A21: 20 | B21: 약어 | C21: NRS | D21: 엔알에스 | E21: NRS 5점 → 엔알에스 오 점 | F21: 15
A22: 21 | B22: 약어 | C22: GCS | D22: 지씨에스 | E22: GCS: 15점 → 지씨에스 십오 점 | F22: 5
A23: 22 | B23: 약어 | C23: BST | D23: 비에스티 | E23: BST 몇이에요? → 비에스티 몇이에요? | F23: 2
A24: 23 | B24: 약어 | C24: FPRS | D24: 에프피알에스 | E24: FPRS 2점이에요 → 에프피알에스 이 점이에요 | F24: 1
A25: 24 | B25: 약어 | C25: ESRD | D25: 이에스알디 | E25: ESRD라 → 이에스알디라 | F25: 1
A26: 25 | B26: 영문 단어 | C26: MOTOR POWER / motor grade | D26: 모터 파워 / 모터 그레이드 | E26: motor grade도 → 모터 그레이드도 | F26: 2
A27: 26 | B27: 영문 단어 | C27: Alert | D27: 얼럿 | E27: 의식수준은 Alert예요 → 의식수준은 얼럿이에요 | F27: 1 | G27: 조사도 발음에 맞춰 교정(예요→이에요)
A28: 27 | B28: 영문 단어 | C28: stupor | D28: 스투퍼 | E28: 기면(stupor)입니다 → 기면 스투퍼입니다 | F28: 1
A29: 28 | B29: 영문 단어 | C29: Mental | D29: 멘탈 | E29: Mental: 명료함 입니다 → 멘탈, 명료함 입니다 | F29: 1
A30: 29 | B30: 기호 | C30: 괄호 ( ) | D30: 괄호 안 내용도 읽고 기호만 삭제 | E30: 운동 기능(MOTOR POWER) → 운동 기능 모터 파워 | F30: 2
A31: 30 | B31: 기호 | C31: 콜론 (:) — 수치 항목 뒤 | D31: 삭제 | E31: SPO2: 98% → 에스피오투 구십팔 퍼센트 / GCS: 15점 → 지씨에스 십오 점 | F31: 11
A32: 31 | B32: 기호 | C32: 콜론 (:) — 항목 표기 뒤 | D32: 쉼표(짧게 쉼) | E32: 과거력: 고혈압과 당뇨병이 있어요 → 과거력, 고혈압과 당뇨병이 있어요 | F32: 11 | G32: '과거력:', '특이사항:', '통증점수:', 'Mental:' 등
A33: 32 | B33: 기호 | C33: 등호 (=) | D33: 삭제 | E33: 활력징후 = V/S: 혈압 75/40 mmHg → 활력징후 브이에스, 혈압 칠십오에 사십 엠엠에이치지 | F33: 4
